[2025-08-31T17:53:18.840+0000] {taskinstance.py:1956} INFO - Dependencies all met for dep_context=non-requeueable deps ti=<TaskInstance: snowflake_connection_test.test_snowflake_connection manual__2025-08-31T17:53:14.620187+00:00 [queued]>
[2025-08-31T17:53:18.862+0000] {taskinstance.py:1956} INFO - Dependencies all met for dep_context=requeueable deps ti=<TaskInstance: snowflake_connection_test.test_snowflake_connection manual__2025-08-31T17:53:14.620187+00:00 [queued]>
[2025-08-31T17:53:18.864+0000] {taskinstance.py:2170} INFO - Starting attempt 1 of 1
[2025-08-31T17:53:18.931+0000] {taskinstance.py:2191} INFO - Executing <Task(SnowflakeOperator): test_snowflake_connection> on 2025-08-31 17:53:14.620187+00:00
[2025-08-31T17:53:18.944+0000] {standard_task_runner.py:60} INFO - Started process 1367 to run task
[2025-08-31T17:53:18.978+0000] {standard_task_runner.py:87} INFO - Running: ['***', 'tasks', 'run', 'snowflake_connection_test', 'test_snowflake_connection', 'manual__2025-08-31T17:53:14.620187+00:00', '--job-id', '3', '--raw', '--subdir', 'DAGS_FOLDER/snowflake_connection_test_dag.py', '--cfg-path', '/tmp/tmpy0hd5tjp']
[2025-08-31T17:53:19.104+0000] {standard_task_runner.py:88} INFO - Job 3: Subtask test_snowflake_connection
[2025-08-31T17:53:19.460+0000] {task_command.py:423} INFO - Running <TaskInstance: snowflake_connection_test.test_snowflake_connection manual__2025-08-31T17:53:14.620187+00:00 [running]> on host ea85b8cb7b29
[2025-08-31T17:53:19.890+0000] {taskinstance.py:2480} INFO - Exporting env vars: AIRFLOW_CTX_DAG_OWNER='***' AIRFLOW_CTX_DAG_ID='snowflake_connection_test' AIRFLOW_CTX_TASK_ID='test_snowflake_connection' AIRFLOW_CTX_EXECUTION_DATE='2025-08-31T17:53:14.620187+00:00' AIRFLOW_CTX_TRY_NUMBER='1' AIRFLOW_CTX_DAG_RUN_ID='manual__2025-08-31T17:53:14.620187+00:00'
[2025-08-31T17:53:19.896+0000] {sql.py:276} INFO - Executing: SELECT CURRENT_USER(), CURRENT_ROLE(), CURRENT_WAREHOUSE(), CURRENT_DATABASE(), CURRENT_SCHEMA();
[2025-08-31T17:53:19.943+0000] {base.py:83} INFO - Using connection ID 'snowflake_default' for task execution.
[2025-08-31T17:53:19.974+0000] {base.py:83} INFO - Using connection ID 'snowflake_default' for task execution.
[2025-08-31T17:53:19.976+0000] {connection.py:370} INFO - Snowflake Connector for Python Version: 3.6.0, Python Version: 3.8.18, Platform: Linux-5.15.167.4-microsoft-standard-WSL2-x86_64-with-glibc2.34
[2025-08-31T17:53:19.979+0000] {connection.py:1171} INFO - This connection is in OCSP Fail Open Mode. TLS Certificates would be checked for validity and revocation status. Any other Certificate Revocation related exceptions or OCSP Responder failures would be disregarded in favor of connectivity.
[2025-08-31T17:53:21.586+0000] {connection.py:547} WARNING - Certificate did not match expected hostname: oendpfo-zbb25646.snowflakecomputing.com.snowflakecomputing.com. Certificate: {'subject': ((('commonName', '*.prod3.us-west-2.snowflakecomputing.com'),),), 'subjectAltName': [('DNS', '*.prod3.us-west-2.snowflakecomputing.com'), ('DNS', '*.us-west-2.snowflakecomputing.com'), ('DNS', '*.global.snowflakecomputing.com'), ('DNS', '*.snowflakecomputing.com'), ('DNS', '*.prod3.us-west-2.aws.snowflakecomputing.com')]}
[2025-08-31T17:53:21.600+0000] {connectionpool.py:824} WARNING - Retrying (Retry(total=0, connect=None, read=None, redirect=None, status=None)) after connection broken by 'SSLError(CertificateError("hostname 'oendpfo-zbb25646.snowflakecomputing.com.snowflakecomputing.com' doesn't match either of '*.prod3.us-west-2.snowflakecomputing.com', '*.us-west-2.snowflakecomputing.com', '*.global.snowflakecomputing.com', '*.snowflakecomputing.com', '*.prod3.us-west-2.aws.snowflakecomputing.com'"))': /session/v1/login-request?request_id=d8d19387-c526-40ad-bcad-664e5cd73254&databaseName=SAP_ANALYTICS_DB&schemaName=RAW_STAGING&warehouse=ETL_WH&roleName=ETL_ROLE&request_guid=a0526c56-46f4-42b2-b8a1-31095a58c043
[2025-08-31T17:53:22.683+0000] {connection.py:547} WARNING - Certificate did not match expected hostname: oendpfo-zbb25646.snowflakecomputing.com.snowflakecomputing.com. Certificate: {'subject': ((('commonName', '*.prod3.us-west-2.snowflakecomputing.com'),),), 'subjectAltName': [('DNS', '*.prod3.us-west-2.snowflakecomputing.com'), ('DNS', '*.us-west-2.snowflakecomputing.com'), ('DNS', '*.global.snowflakecomputing.com'), ('DNS', '*.snowflakecomputing.com'), ('DNS', '*.prod3.us-west-2.aws.snowflakecomputing.com')]}
[2025-08-31T17:53:22.704+0000] {network.py:1024} ERROR - Failed to get the response. Hanging? method: post, url: https://OENDPFO-ZBB25646.snowflakecomputing.com.snowflakecomputing.com:443/session/v1/login-request?request_id=d8d19387-c526-40ad-bcad-664e5cd73254&databaseName=SAP_ANALYTICS_DB&schemaName=RAW_STAGING&warehouse=ETL_WH&roleName=ETL_ROLE&request_guid=a0526c56-46f4-42b2-b8a1-31095a58c043, headers:{'Content-Type': 'application/json', 'accept': 'application/snowflake', 'User-Agent': 'PythonConnector/3.6.0 (Linux-5.15.167.4-microsoft-standard-WSL2-x86_64-with-glibc2.34) CPython/3.8.18', 'Content-Encoding': 'gzip'}, data: {"data": {"CLIENT_APP_ID": "PythonConnector", "CLIENT_APP_VERSION": "3.6.0", "SVN_REVISION": null, "ACCOUNT_NAME": "OENDPFO-ZBB25646", "LOGIN_NAME": "AmineBoktaya", "CLIENT_ENVIRONMENT": {"APPLICATION": "AIRFLOW", "OS": "Linux", "OS_VERSION": "Linux-5.15.167.4-microsoft-standard-WSL2-x86_64-with-glibc2.34", "PYTHON_VERSION": "3.8.18", "PYTHON_RUNTIME": "CPython", "PYTHON_COMPILER": "GCC 12.2.0", "OCSP_MODE": "FAIL_OPEN", "TRACING": 20, "LOGIN_TIMEOUT": null, "NETWORK_TIMEOUT": null, "SOCKET_TIMEOUT": null}, "PASSWORD": "**** "SESSION_PARAMETERS": {"CLIENT_PREFETCH_THREADS": 4}}}
[2025-08-31T17:53:24.665+0000] {connection.py:547} WARNING - Certificate did not match expected hostname: oendpfo-zbb25646.snowflakecomputing.com.snowflakecomputing.com. Certificate: {'subject': ((('commonName', '*.prod3.us-west-2.snowflakecomputing.com'),),), 'subjectAltName': [('DNS', '*.prod3.us-west-2.snowflakecomputing.com'), ('DNS', '*.us-west-2.snowflakecomputing.com'), ('DNS', '*.global.snowflakecomputing.com'), ('DNS', '*.snowflakecomputing.com'), ('DNS', '*.prod3.us-west-2.aws.snowflakecomputing.com')]}
[2025-08-31T17:53:24.667+0000] {connectionpool.py:824} WARNING - Retrying (Retry(total=0, connect=None, read=None, redirect=None, status=None)) after connection broken by 'SSLError(CertificateError("hostname 'oendpfo-zbb25646.snowflakecomputing.com.snowflakecomputing.com' doesn't match either of '*.prod3.us-west-2.snowflakecomputing.com', '*.us-west-2.snowflakecomputing.com', '*.global.snowflakecomputing.com', '*.snowflakecomputing.com', '*.prod3.us-west-2.aws.snowflakecomputing.com'"))': /session/v1/login-request?request_id=a2d33812-afce-4ac9-bbfa-c74207761563&databaseName=SAP_ANALYTICS_DB&schemaName=RAW_STAGING&warehouse=ETL_WH&roleName=ETL_ROLE&request_guid=2a2b9928-fbc8-4548-999f-195ee60dedfa
[2025-08-31T17:53:25.675+0000] {connection.py:547} WARNING - Certificate did not match expected hostname: oendpfo-zbb25646.snowflakecomputing.com.snowflakecomputing.com. Certificate: {'subject': ((('commonName', '*.prod3.us-west-2.snowflakecomputing.com'),),), 'subjectAltName': [('DNS', '*.prod3.us-west-2.snowflakecomputing.com'), ('DNS', '*.us-west-2.snowflakecomputing.com'), ('DNS', '*.global.snowflakecomputing.com'), ('DNS', '*.snowflakecomputing.com'), ('DNS', '*.prod3.us-west-2.aws.snowflakecomputing.com')]}
[2025-08-31T17:53:25.696+0000] {network.py:1024} ERROR - Failed to get the response. Hanging? method: post, url: https://OENDPFO-ZBB25646.snowflakecomputing.com.snowflakecomputing.com:443/session/v1/login-request?request_id=a2d33812-afce-4ac9-bbfa-c74207761563&databaseName=SAP_ANALYTICS_DB&schemaName=RAW_STAGING&warehouse=ETL_WH&roleName=ETL_ROLE&request_guid=2a2b9928-fbc8-4548-999f-195ee60dedfa, headers:{'Content-Type': 'application/json', 'accept': 'application/snowflake', 'User-Agent': 'PythonConnector/3.6.0 (Linux-5.15.167.4-microsoft-standard-WSL2-x86_64-with-glibc2.34) CPython/3.8.18', 'Content-Encoding': 'gzip'}, data: {"data": {"CLIENT_APP_ID": "PythonConnector", "CLIENT_APP_VERSION": "3.6.0", "SVN_REVISION": null, "ACCOUNT_NAME": "OENDPFO-ZBB25646", "LOGIN_NAME": "AmineBoktaya", "CLIENT_ENVIRONMENT": {"APPLICATION": "AIRFLOW", "OS": "Linux", "OS_VERSION": "Linux-5.15.167.4-microsoft-standard-WSL2-x86_64-with-glibc2.34", "PYTHON_VERSION": "3.8.18", "PYTHON_RUNTIME": "CPython", "PYTHON_COMPILER": "GCC 12.2.0", "OCSP_MODE": "FAIL_OPEN", "TRACING": 20, "LOGIN_TIMEOUT": null, "NETWORK_TIMEOUT": null, "SOCKET_TIMEOUT": null}, "PASSWORD": "**** "SESSION_PARAMETERS": {"CLIENT_PREFETCH_THREADS": 4}}}
[2025-08-31T17:53:25.720+0000] {taskinstance.py:2698} ERROR - Task failed with exception
Traceback (most recent call last):
  File "/home/airflow/.local/lib/python3.8/site-packages/snowflake/connector/connection.py", line 1305, in _authenticate
    auth.authenticate(
  File "/home/airflow/.local/lib/python3.8/site-packages/snowflake/connector/auth/_auth.py", line 250, in authenticate
    ret = self._rest._post_request(
  File "/home/airflow/.local/lib/python3.8/site-packages/snowflake/connector/network.py", line 729, in _post_request
    ret = self.fetch(
  File "/home/airflow/.local/lib/python3.8/site-packages/snowflake/connector/network.py", line 838, in fetch
    ret = self._request_exec_wrapper(
  File "/home/airflow/.local/lib/python3.8/site-packages/snowflake/connector/network.py", line 974, in _request_exec_wrapper
    raise e
  File "/home/airflow/.local/lib/python3.8/site-packages/snowflake/connector/network.py", line 890, in _request_exec_wrapper
    self._handle_unknown_error(method, full_url, headers, data, conn)
  File "/home/airflow/.local/lib/python3.8/site-packages/snowflake/connector/network.py", line 1029, in _handle_unknown_error
    Error.errorhandler_wrapper(
  File "/home/airflow/.local/lib/python3.8/site-packages/snowflake/connector/errors.py", line 290, in errorhandler_wrapper
    handed_over = Error.hand_to_other_handler(
  File "/home/airflow/.local/lib/python3.8/site-packages/snowflake/connector/errors.py", line 348, in hand_to_other_handler
    connection.errorhandler(connection, cursor, error_class, error_value)
  File "/home/airflow/.local/lib/python3.8/site-packages/snowflake/connector/errors.py", line 221, in default_errorhandler
    raise error_class(
snowflake.connector.errors.OperationalError: 250003: 250003: Failed to get the response. Hanging? method: post, url: https://OENDPFO-ZBB25646.snowflakecomputing.com.snowflakecomputing.com:443/session/v1/login-request?request_id=d8d19387-c526-40ad-bcad-664e5cd73254&databaseName=SAP_ANALYTICS_DB&schemaName=RAW_STAGING&warehouse=ETL_WH&roleName=ETL_ROLE&request_guid=a0526c56-46f4-42b2-b8a1-31095a58c043

The above exception was the direct cause of the following exception:

Traceback (most recent call last):
  File "/home/airflow/.local/lib/python3.8/site-packages/airflow/models/taskinstance.py", line 433, in _execute_task
    result = execute_callable(context=context, **execute_callable_kwargs)
  File "/home/airflow/.local/lib/python3.8/site-packages/airflow/providers/common/sql/operators/sql.py", line 282, in execute
    output = hook.run(
  File "/home/airflow/.local/lib/python3.8/site-packages/airflow/providers/snowflake/hooks/snowflake.py", line 382, in run
    with closing(self.get_conn()) as conn:
  File "/home/airflow/.local/lib/python3.8/site-packages/airflow/providers/snowflake/hooks/snowflake.py", line 276, in get_conn
    conn = connector.connect(**conn_config)
  File "/home/airflow/.local/lib/python3.8/site-packages/snowflake/connector/__init__.py", line 54, in Connect
    return SnowflakeConnection(**kwargs)
  File "/home/airflow/.local/lib/python3.8/site-packages/snowflake/connector/connection.py", line 413, in __init__
    self.connect(**kwargs)
  File "/home/airflow/.local/lib/python3.8/site-packages/snowflake/connector/connection.py", line 703, in connect
    self.__open_connection()
  File "/home/airflow/.local/lib/python3.8/site-packages/snowflake/connector/connection.py", line 1006, in __open_connection
    self.authenticate_with_retry(self.auth_class)
  File "/home/airflow/.local/lib/python3.8/site-packages/snowflake/connector/connection.py", line 1277, in authenticate_with_retry
    self._authenticate(auth_instance)
  File "/home/airflow/.local/lib/python3.8/site-packages/snowflake/connector/connection.py", line 1349, in _authenticate
    raise auth_op from e
  File "/home/airflow/.local/lib/python3.8/site-packages/snowflake/connector/connection.py", line 1326, in _authenticate
    auth_instance.handle_timeout(
  File "/home/airflow/.local/lib/python3.8/site-packages/snowflake/connector/auth/by_plugin.py", line 212, in handle_timeout
    raise error
snowflake.connector.errors.OperationalError: 250001: 250001: Could not connect to Snowflake backend after 2 attempt(s).Aborting
[2025-08-31T17:53:25.744+0000] {taskinstance.py:1138} INFO - Marking task as FAILED. dag_id=snowflake_connection_test, task_id=test_snowflake_connection, execution_date=20250831T175314, start_date=20250831T175318, end_date=20250831T175325
[2025-08-31T17:53:25.795+0000] {standard_task_runner.py:107} ERROR - Failed to execute job 3 for task test_snowflake_connection (250001: 250001: Could not connect to Snowflake backend after 2 attempt(s).Aborting; 1367)
[2025-08-31T17:53:25.828+0000] {local_task_job_runner.py:234} INFO - Task exited with return code 1
[2025-08-31T17:53:25.874+0000] {taskinstance.py:3280} INFO - 0 downstream tasks scheduled from follow-on schedule check
